Workbook

Sheet 貸借対照表
A1: 貸借対照表 （単位：千円）
A2: 【凡例】緑=合計（確定）/ 水色=小計（確定）/ 黄色=自動入力（要確認・科目名を修正してください）/ 灰色=未入力（手動入力）
A3: 科目 | B3: KAISEI第5期2023年7月期決算報告書 | C3: KAISEI第6期2024年7月期決算報告書 | D3: KAISEI第7期2025年7月期決算報告書 | E3: 増減額 (2→3期) | F3: 増減率 (2→3期)
A4: 【流動資産】
A5: 現金及び預金 | B5: 7028 | C5: 7028 | D5: 7028
A6: 受取手形 | B6: 10010 | C6: 10010 | D6: 10010
A7: 売掛金 | B7: 600 | C7: 600 | D7: 600
A8: 商品・製品 | B8: 724 | C8: 724 | D8: 724
A9: 仕掛品
A10: 原材料・貯蔵品
A11: 前払費用
A12: 未収入金
A13: その他流動資産
A14: 流動資産合計 | B14: 18364 | C14: 18364 | D14: 18364
A15: 【固定資産】
A16: 有形固定資産計 | B16: 10960 | C16: 10960 | D16: 10960
A17: 建物・構築物
A18: 機械及び装置
A19: 車両運搬具 | B19: 8093 | C19: 8093 | D19: 8093
A20: 工具器具備品
A21: 土地
A22: 減価償却累計額 | B22: 2741 | C22: 2741 | D22: 2741
A23: 無形固定資産合計 | B23: 2166 | C23: 2166 | D23: 2166
A24: 投資その他の資産合計 | B24: 2090 | C24: 2090 | D24: 2090
A25: 敷金・保証金 | B25: 46 | C25: 46 | D25: 46
A26: 繰延税金資産 | B26: 30 | C26: 30 | D26: 30
A27: その他投資資産
A28: 固定資産合計 | B28: 13126 | C28: 13126 | D28: 13126
A29: 資産合計 | B29: 31491 | C29: 31491 | D29: 31491
A31: 【流動負債】
A32: 支払手形
A33: 買掛金
A34: 短期借入金
A35: 1年内返済長期借入金
A36: 未払金
A37: 未払費用
A38: 未払法人税等
A39: 前受金
A40: 預り金
A41: 賞与引当金
...

Sheet 損益計算書
A1: 損益計算書 （単位：千円）
A2: 【凡例】緑=合計（確定）/ 水色=小計（確定）/ 黄色=自動入力（要確認・科目名を修正してください）/ 灰色=未入力（手動入力）
A3: 科目 | B3: KAISEI第5期2023年7月期決算報告書 | C3: KAISEI第6期2024年7月期決算報告書 | D3: KAISEI第7期2025年7月期決算報告書 | E3: 増減額 (2→3期) | F3: 増減率 (2→3期)
A4: 売上高 | B4: 30918 | C4: 30918 | D4: 30918
A5: 【売上原価】
A6: 期首棚卸高
A7: 当期仕入高
A8: 当期製品製造原価 | B8: 4148 | C8: 4148 | D8: 4148
A9: 期末棚卸高
A10: 売上原価合計 | B10: 4148 | C10: 4148 | D10: 4148
A11: 売上総利益（損失） | B11: 26770 | C11: 26770 | D11: 26770
A12: 販売費及び一般管理費合計 | B12: 62088 | C12: 62088 | D12: 62088
A13: 営業利益（損失） | B13: -35318 | C13: -35318 | D13: -35318
A14: 【営業外収益】
A15: 受取利息・配当金 | B15: 0 | C15: 0 | D15: 0
A16: 雑収入 | B16: 2 | C16: 2 | D16: 2
A17: その他営業外収益 | B17: 3203 | C17: 3203 | D17: 3203
A18: 営業外収益合計 | B18: 3206 | C18: 3206 | D18: 3206
A19: 【営業外費用】
A20: 支払利息・割引料 | B20: 301 | C20: 301 | D20: 301
A21: 為替差損
A22: その他営業外費用
A23: 営業外費用合計 | B23: 301 | C23: 301 | D23: 301
A24: 経常利益（損失） | B24: -32413 | C24: -32413 | D24: -32413
A25: 【特別利益】
A26: 固定資産売却益
A27: その他特別利益
A28: 特別利益合計
A29: 【特別損失】
A30: 固定資産売却損・廃棄損
A31: 減損損失
A32: その他特別損失
A33: 特別損失合計
A34: 税引前当期純利益（損失） | B34: -32413 | C34: -32413 | D34: -32413
A35: 法人税等 | B35: 30 | C35: 30 | D35: 30
A36: 当期純利益（損失） | B36: -32443 | C36: -32443 | D36: -32443

Sheet 販売費及び一般管理費
A1: 販売費及び一般管理費 （単位：千円）
A2: 【凡例】緑=合計（確定）/ 水色=小計（確定）/ 黄色=自動入力（要確認・科目名を修正してください）/ 灰色=未入力（手動入力）
A3: 科目 | B3: KAISEI第5期2023年7月期決算報告書 | C3: KAISEI第6期2024年7月期決算報告書 | D3: KAISEI第7期2025年7月期決算報告書 | E3: 増減額 (2→3期) | F3: 増減率 (2→3期)
A4: 給料・賞与 | B4: 24799 | C4: 24799 | D4: 24799
A5: 法定福利費 | B5: 4165 | C5: 4165 | D5: 4165
A6: 福利厚生費 | B6: 1678 | C6: 1678 | D6: 1678
A7: 退職給付費用 | B7: 2741 | C7: 2741 | D7: 2741
A8: 減価償却費 | B8: 3799 | C8: 3799 | D8: 3799
A9: 租税公課 | B9: 2144 | C9: 2144 | D9: 2144
A10: 賃借料 | B10: 1088 | C10: 1088 | D10: 1088
A11: 賞与引当金繰入 | B11: 1347 | C11: 1347 | D11: 1347
A12: 旅費交通費 | B12: 2112 | C12: 2112 | D12: 2112
A13: 広告宣伝費 | B13: 10 | C13: 10 | D13: 10
A14: 販売促進費 | B14: 60 | C14: 60 | D14: 60
A15: 発送配達費 | B15: 806 | C15: 806 | D15: 806
... A29: 会議費 | B29: 240 | C29: 240 | D29: 240
A30: 研究開発費
A31: その他販管費
A32: 販売費及び一般管理費合計 | B32: 62088 | C32: 62088 | D32: 62088

Sheet 業界平均比較・アラート
A1: 業界平均比較・財務アラート
A2: 【業種選択】 | B2: サービス業 | C2: ← ここで業種を選択してください
A3: 【判定凡例】 | B3: ● 要注意（業界平均と20%超乖離） | D3: △ 注意（業界平均と10%超乖離） | F3: ○ 正常範囲 | H3: ─ データなし
A4: 指標名 | B4: 計算式 | C4: 第1期実績 | D4: 第2期実績 | E4: 第3期実績 | F4: 業界平均 | G4: 差異(3期-平均) | H4: 判定 | I4: コメント
A5: 【収益性分析】
A6: 売上総利益率 | B6: 売上総利益 ÷ 売上高 | C6: =IFERROR((IFERROR(損益計算書!B11,0))/(IFERROR(損益計算書!B4,0)),"") -> 0.86583867 | D6: =IFERROR((IFERROR(損益計算書!C11,0))/(IFERROR(損益計算書!C4,0)),"") -> 0.86583867 | E6: =IFERROR((IFERROR(損益計算書!D11,0))/(IFERROR(損益計算書!D4,0)),"") -> 0.86583867 | F6: =IFERROR(VLOOKUP($B$2,業界データ!$A:$O,2,0),"") -> 0.6 | G6: =IFERROR(IF(OR(E6="",F6=""),"",E6-F6),"") -> 0.26583867 | H6: =IF(F6="","─",IF(ABS(G6)>ABS(F6)*0.2,"●",IF(ABS(G6)>ABS(F6)*0.1,"△","○"))) -> ● | I6: =IF(F6="","",IF(ABS(G6)>ABS(F6)*0.2,IF(G6>0,"売上総利益率が業界平均より大幅に高い","売上総利益率が業界平均より大幅に低い"),"正常範囲")) -> 売上総利益率が業界平均より大幅に高い
A7: 営業利益率 | B7: 営業利益 ÷ 売上高 | C7: =IFERROR((IFERROR(損益計算書!B13,0))/(IFERROR(損益計算書!B4,0)),"") -> -1.1423119 | D7: =IFERROR((IFERROR(損益計算書!C13,0))/(IFERROR(損益計算書!C4,0)),"") -> -1.1423119 | E7: =IFERROR((IFERROR(損益計算書!D13,0))/(IFERROR(損益計算書!D4,0)),"") -> -1.1423119 | F7: =IFERROR(VLOOKUP($B$2,業界データ!$A:$O,3,0),"") -> 0.05 | G7: =IFERROR(IF(OR(E7="",F7=""),"",E7-F7),"") -> -1.1923119 | H7: =IF(F7="","─",IF(ABS(G7)>ABS(F7)*0.2,"●",IF(ABS(G7)>ABS(F7)*0.1,"△","○"))) -> ● | I7: =IF(F7="","",IF(ABS(G7)>ABS(F7)*0.2,IF(G7>0,"営業利益率が業界平均より大幅に高い","営業利益率が業界平均より大幅に低い"),"正常範囲")) -> 営業利益率が業界平均より大幅に低い
A8: 経常利益率 | B8: 経常利益 ÷ 売上高 | C8: =IFERROR((IFERROR(損益計算書!B24,0))/(IFERROR(損益計算書!B4,0)),"") -> -1.0483537 | D8: =IFERROR((IFERROR(損益計算書!C24,0))/(IFERROR(損益計算書!C4,0)),"") -> -1.0483537 | E8: =IFERROR((IFERROR(損益計算書!D24,0))/(IFERROR(損益計算書!D4,0)),"") -> -1.0483537 | F8: =IFERROR(VLOOKUP($B$2,業界データ!$A:$O,4,0),"") -> 0.06 | G8: =IFERROR(IF(OR(E8="",F8=""),"",E8-F8),"") -> -1.1083537 | H8: =IF(F8="","─",IF(ABS(G8)>ABS(F8)*0.2,"●",IF(ABS(G8)>ABS(F8)*0.1,"△","○"))) -> ● | I8: =IF(F8="","",IF(ABS(G8)>ABS(F8)*0.2,IF(G8>0,"経常利益率が業界平均より大幅に高い","経常利益率が業界平均より大幅に低い"),"正常範囲")) -> 経常利益率が業界平均より大幅に低い
A9: 純利益率 | B9: 当期純利益 ÷ 売上高 | C9: =IFERROR((IFERROR(損益計算書!B36,0))/(IFERROR(損益計算書!B4,0)),"") -> -1.049324 | D9: =IFERROR((IFERROR(損益計算書!C36,0))/(IFERROR(損益計算書!C4,0)),"") -> -1.049324 | E9: =IFERROR((IFERROR(損益計算書!D36,0))/(IFERROR(損益計算書!D4,0)),"") -> -1.049324 | F9: =IFERROR(VLOOKUP($B$2,業界データ!$A:$O,5,0),"") -> 0.04 | G9: =IFERROR(IF(OR(E9="",F9=""),"",E9-F9),"") -> -1.089324 | H9: =IF(F9="","─",IF(ABS(G9)>ABS(F9)*0.2,"●",IF(ABS(G9)>ABS(F9)*0.1,"△","○"))) -> ● | I9: =IF(F9="","",IF(ABS(G9)>ABS(F9)*0.2,IF(G9>0,"純利益率が業界平均より大幅に高い","純利益率が業界平均より大幅に低い"),"正常範囲")) -> 純利益率が業界平均より大幅に低い
A10: 人件費率 | B10: 給料賞与 ÷ 売上高 | C10: =IFERROR((IFERROR(販売費及び一般管理費!B4,0))/(IFERROR(損益計算書!B4,0)),"") -> 0.8020894 | D10: =IFERROR((IFERROR(販売費及び一般管理費!C4,0))/(IFERROR(損益計算書!C4,0)),"") -> 0.8020894 | E10: =IFERROR((IFERROR(販売費及び一般管理費!D4,0))/(IFERROR(損益計算書!D4,0)),"") -> 0.8020894 | F10: =IFERROR(VLOOKUP($B$2,業界データ!$A:$O,9,0),"") -> 0.4 | G10: =IFERROR(IF(OR(E10="",F10=""),"",E10-F10),"") -> 0.4020894 | H10: =IF(F10="","─",IF(ABS(G10)>ABS(F10)*0.2,"●",IF(ABS(G10)>ABS(F10)*0.1,"△","○"))) -> ● | I10: =IF(F10="","",IF(ABS(G10)>ABS(F10)*0.2,IF(G10>0,"人件費率が業界平均より大幅に低い","人件費率が業界平均より大幅に高い"),"正常範囲")) -> 人件費率が業界平均より大幅に低い
A12: 【安全性分析】
A13: 自己資本比率 | B13: 純資産 ÷ 資産合計 | C13: =IFERROR(貸借対照表!B60/貸借対照表!B29,"") -> -0.78901908 | D13: =IFERROR(貸借対照表!C60/貸借対照表!C29,"") -> -0.78901908 | E13: =IFERROR(貸借対照表!D60/貸借対照表!D29,"") -> -0.78901908 | F13: =IFERROR(VLOOKUP($B$2,業界データ!$A:$O,6,0),"") -> 0.35 | G13: =IFERROR(IF(OR(E13="",F13=""),"",E13-F13),"") -> -1.1390191 | H13: =IF(F13="","─",IF(ABS(G13)>ABS(F13)*0.2,"●",IF(ABS(G13)>ABS(F13)*0.1,"△","○"))) -> ● | I13: =IF(F13="","",IF(ABS(G13)>ABS(F13)*0.2,IF(G13>0,"自己資本比率が業界平均より大幅に高い","自己資本比率が業界平均より大幅に低い"),"正常範囲")) -> 自己資本比率が業界平均より大幅に低い
A14: 流動比率 | B14: 流動資産 ÷ 流動負債 | C14: =IFERROR(貸借対照表!B14/IF(貸借対照表!B43=0,1,貸借対照表!B43),"") -> 0.32595538 | D14: =IFERROR(貸借対照表!C14/IF(貸借対照表!C43=0,1,貸借対照表!C43),"") -> 0.32595538 | E14: =IFERROR(貸借対照表!D14/IF(貸借対照表!D43=0,1,貸借対照表!D43),"") -> 0.32595538 | F14: =IFERROR(VLOOKUP($B$2,業界データ!$A:$O,7,0),"") -> 1.4 | G14: =IFERROR(IF(OR(E14="",F14=""),"",E14-F14),"") -> -1.0740446 | H14: =IF(F14="","─",IF(ABS(G14)>ABS(F14)*0.2,"●",IF(ABS(G14)>ABS(F14)*0.1,"△","○"))) -> ● | I14: =IF(F14="","",IF(ABS(G14)>ABS(F14)*0.2,IF(G14>0,"流動比率が業界平均より大幅に高い","流動比率が業界平均より大幅に低い"),"正常範囲")) -> 流動比率が業界平均より大幅に低い
A15: 固定比率 | B15: 固定資産 ÷ 純資産 | C15: =IFERROR(貸借対照表!B28/IF(貸借対照表!B60=0,1,貸借対照表!B60),"") -> -0.52827303 | D15: =IFERROR(貸借対照表!C28/IF(貸借対照表!C60=0,1,貸借対照表!C60),"") -> -0.52827303 | E15: =IFERROR(貸借対照表!D28/IF(貸借対照表!D60=0,1,貸借対照表!D60),"") -> -0.52827303 | F15: =IFERROR(VLOOKUP($B$2,業界データ!$A:$O,8,0),"") -> 0.6 | G15: =IFERROR(IF(OR(E15="",F15=""),"",E15-F15),"") -> -1.128273 | H15: =IF(F15="","─",IF(ABS(G15)>ABS(F15)*0.2,"●",IF(ABS(G15)>ABS(F15)*0.1,"△","○"))) -> ● | I15: =IF(F15="","",IF(ABS(G15)>ABS(F15)*0.2,IF(G15>0,"固定比率が業界平均より大幅に低い","固定比率が業界平均より大幅に高い"),"正常範囲")) -> 固定比率が業界平均より大幅に高い
A16: ROA | B16: 経常利益 ÷ 資産合計 | C16: =IFERROR(損益計算書!B24/IF(貸借対照表!B29=0,1,貸借対照表!B29),"") -> -1.0292782 | D16: =IFERROR(損益計算書!C24/IF(貸借対照表!C29=0,1,貸借対照表!C29),"") -> -1.0292782 | E16: =IFERROR(損益計算書!D24/IF(貸借対照表!D29=0,1,貸借対照表!D29),"") -> -1.0292782 | F16: =IFERROR(VLOOKUP($B$2,業界データ!$A:$O,10,0),"") -> 0.04 | G16: =IFERROR(IF(OR(E16="",F16=""),"",E16-F16),"") -> -1.0692782 | H16: =IF(F16="","─",IF(ABS(G16)>ABS(F16)*0.2,"●",IF(ABS(G16)>ABS(F16)*0.1,"△","○"))) -> ● | I16: =IF(F16="","",IF(ABS(G16)>ABS(F16)*0.2,IF(G16>0,"ROAが業界平均より大幅に高い","ROAが業界平均より大幅に低い"),"正常範囲")) -> ROAが業界平均より大幅に低い
A17: ROE | B17: 当期純利益 ÷ 純資産 | C17: =IFERROR(損益計算書!B36/IF(貸借対照表!B60=0,1,貸借対照表!B60),"") -> 1.305711 | D17: =IFERROR(損益計算書!C36/IF(貸借対照表!C60=0,1,貸借対照表!C60),"") -> 1.305711 | E17: =IFERROR(損益計算書!D36/IF(貸借対照表!D60=0,1,貸借対照表!D60),"") -> 1.305711 | F17: =IFERROR(VLOOKUP($B$2,業界データ!$A:$O,11,0),"") -> 0.1 | G17: =IFERROR(IF(OR(E17="",F17=""),"",E17-F17),"") -> 1.205711 | H17: =IF(F17="","─",IF(ABS(G17)>ABS(F17)*0.2,"●",IF(ABS(G17)>ABS(F17)*0.1,"△","○"))) -> ● | I17: =IF(F17="","",IF(ABS(G17)>ABS(F17)*0.2,IF(G17>0,"ROEが業界平均より大幅に高い","ROEが業界平均より大幅に低い"),"正常範囲")) -> ROEが業界平均より大幅に高い
A19: 【成長性分析】
A20: 売上高成長率（1→2期） | B20: (第2期売上高 - 第1期売上高) ÷ 第1期売上高 | C20: ─ | D20: =IFERROR(IF(OR(損益計算書!C4="",損益計算書!B4=0),"",(損益計算書!C4-損益計算書!B4)/損益計算書!B4),"") -> 0 | E20: ─ | F20: ─ | G20: =IFERROR(IF(OR(D20="",F20="","─"=F20),"",D20-F20),"") | H20: =IF(OR(G20="","─"=G20),"─","○") -> ─ | I20: =IF(OR(G20="","─"=G20),"",IF(D20>0,"売上高が成長しています","売上高が減少しています"))
A21: 売上高成長率（2→3期） | B21: (第3期売上高 - 第2期売上高) ÷ 第2期売上高 | C21: ─ | D21: ─ | E21: =IFERROR(IF(OR(損益計算書!D4="",損益計算書!C4=0),"",(損益計算書!D4-損益計算書!C4)/損益計算書!C4),"") -> 0 | F21: =IFERROR(VLOOKUP($B$2,業界データ!$A:$O,12,0),"") -> 8 | G21: =IFERROR(IF(OR(E21="",F21="","─"=F21),"",E21-F21),"") -> -8 | H21: =IF(OR(G21="","─"=G21),"─","○") -> ○ | I21: =IF(OR(G21="","─"=G21),"",IF(E21>0,"売上高が成長しています","売上高が減少しています")) -> 売上高が減少しています
A23: 【主要財務数値（千円）】
A24: 売上高 | B24: （参照） | C24: =IFERROR(損益計算書!B4,"") -> 30918 | D24: =IFERROR(損益計算書!C4,"") -> 30918 | E24: =IFERROR(損益計算書!D4,"") -> 30918 | F24: ─ | G24: ─ | H24: ─ | I24: ─
A25: 売上総利益 | B25: （参照） | C25: =IFERROR(損益計算書!B11,"") -> 26770 | D25: =IFERROR(損益計算書!C11,"") -> 26770 | E25: =IFERROR(損益計算書!D11,"") -> 26770 | F25: ─ | G25: ─ | H25: ─ | I25: ─
A26: 営業利益 | B26: （参照） | C26: =IFERROR(損益計算書!B13,"") -> -35318 | D26: =IFERROR(損益計算書!C13,"") -> -35318 | E26: =IFERROR(損益計算書!D13,"") -> -35318 | F26: ─ | G26: ─ | H26: ─ | I26: ─
A27: 経常利益 | B27: （参照） | C27: =IFERROR(損益計算書!B24,"") -> -32413 | D27: =IFERROR(損益計算書!C24,"") -> -32413 | E27: =IFERROR(損益計算書!D24,"") -> -32413 | F27: ─ | G27: ─ | H27: ─ | I27: ─
A28: 当期純利益 | B28: （参照） | C28: =IFERROR(損益計算書!B36,"") -> -32443 | D28: =IFERROR(損益計算書!C36,"") -> -32443 | E28: =IFERROR(損益計算書!D36,"") -> -32443 | F28: ─ | G28: ─ | H28: ─ | I28: ─
A29: 純資産 | B29: （参照） | C29: =IFERROR(貸借対照表!B60,"") -> -24847 | D29: =IFERROR(貸借対照表!C60,"") -> -24847 | E29: =IFERROR(貸借対照表!D60,"") -> -24847 | F29: ─ | G29: ─ | H29: ─ | I29: ─
A30: 資産合計 | B30: （参照） | C30: =IFERROR(貸借対照表!B29,"") -> 31491 | D30: =IFERROR(貸借対照表!C29,"") -> 31491 | E30: =IFERROR(貸借対照表!D29,"") -> 31491 | F30: ─ | G30: ─ | H30: ─ | I30: ─
A32: 【注記】 ・業界平均値は中小企業庁データ等をもとにした参考値です。実際の業界平均と異なる場合があります。 ・差異の判定は「第3期実績 - 業界平均」で算出。利益率は高いほど良く、人件費率・固定比率は低いほど良い傾向です。 ・データが未入力の期は空欄になります。第3期（最新期）への入力が完了すると全指標が算出されます。

Sheet 企業価値算定（修正前）
A1: 企業価値算定（修正前） ※帳簿値そのまま使用
A2: 単位：千円 対象期：最新期（第3期）
A3: 【基礎財務データ（3期比較表より自動取得）】
A4: 売上高 | B4: =IFERROR(損益計算書!D4,0) -> 30918 | C4: 損益計算書より
A5: 売上総利益 | B5: =IFERROR(損益計算書!D11,0) -> 26770 | C5: 損益計算書より
A6: 営業利益 | B6: =IFERROR(損益計算書!D13,0) -> -35318 | C6: 損益計算書より
A7: 経常利益 | B7: =IFERROR(損益計算書!D24,0) -> -32413 | C7: 損益計算書より
A8: 当期純利益 | B8: =IFERROR(損益計算書!D36,0) -> -32443 | C8: 損益計算書より
A9: 減価償却費 | B9: =IFERROR(販売費及び一般管理費!D8,0) -> 3799 | C9: 販管費内の減価償却費
A10: 純資産（簿価） | B10: =IFERROR(貸借対照表!D60,0) -> -24847 | C10: 貸借対照表より
A11: 資産合計 | B11: =IFERROR(貸借対照表!D29,0) -> 31491 | C11: 貸借対照表より
A12: 負債合計 | B12: =IFERROR(貸借対照表!D49,0) -> 56339 | C12: 貸借対照表より
A13: 流動負債合計 | B13: =IFERROR(貸借対照表!D43,0) -> 56339 | C13: 貸借対照表より
A14: 固定負債合計 | B14: =IFERROR(貸借対照表!D48,0) -> 0 | C14: 貸借対照表より
A16: EBITDA（営業利益 + 減価償却費） | B16: =B6+B9 -> -31519 | C16: ※売上原価内の減価償却費は別途確認
A17: 有利子負債合計 | B17: =B14+B13 -> 56339 | C17: ※実際は有利子負債のみで計算（借入金等）
A18: 実効税率（入力） | B18: 0.3 | C18: 黄色セルは変更可能（デフォルト30%）
A20: 【評価マルチプル（変更可能）】
A21: 評価手法 | B21: マルチプル | C21: 根拠・出典
A22: 年買法 係数（低） | B22: 2 | C22: 2年分の利益（保守的）
A23: 年買法 係数（高） | B23: 4 | C23: 4年分の利益（楽観的）
A24: EV/EBITDA倍率 | B24: 12.17 | C24: IT業界中央値（yfinance参照）
A25: EV/売上高倍率 | B25: 2.16 | C25: IT業界中央値（yfinance参照）
A26: PBR倍率 | B26: 2.87 | C26: IT業界中央値（yfinance参照）
A27: PER倍率 | B27: 23.42 | C27: IT業界中央値（yfinance参照）
A29: 【各評価手法による企業価値算定（千円）】
A30: 評価手法 | B30: 算出根拠 | C30: 事業価値(EV) | D30: 株主価値(EQ) | E30: 備考
A31: ①年倍法（保守的・2年） | C31: =IFERROR(B10+B7*B22,"") -> -89673 | D31: =IFERROR(C31-B17,"") -> -146012 | E31: 修正純資産 + 経常利益×2年
A32: ②年倍法（楽観的・4年） | C32: =IFERROR(B10+B7*B23,"") -> -154499 | D32: =IFERROR(C32-B17,"") -> -210838 | E32: 修正純資産 + 経常利益×4年
A33: ③EV/EBITDA法 | C33: =IFERROR(B16*B24,"") -> -383586.23 | D33: =IFERROR(C33-B17,"") -> -439925.23 | E33: EBITDA × 12.17倍
A34: ④EV/売上高法 | C34: =IFERROR(B4*B25,"") -> 66782.88 | D34: =IFERROR(C34-B17,"") -> 10443.88 | E34: 売上高 × 2.16倍
A35: ⑤PBR法（株主価値ベース） | C35: =IFERROR(D35+B17,"") -> -14971.89 | D35: =IFERROR(B10*B26,"") -> -71310.89 | E35: 純資産 × 2.87倍
A36: ⑥PER法 | C36: =IFERROR(IF(B8>0,B8*B27+B17,"赤字のため算定不可"),"") -> 赤字のため算定不可 | D36: =IFERROR(C36-B17,"") | E36: 当期純利益 × 23.42倍 + 有利子負債
A37: ⑦純資産法（簿価） | C37: =IFERROR(B11-B12,"") -> -24848 | D37: =IFERROR(B10,"") -> -24847 | E37: 資産合計 - 負債合計
A39: 【評価レンジまとめ（株主価値ベース、千円）】
A40: 指標 | B40: 金額（千円） | C40: 年買法（低） | D40: 年買法（高） | E40: EV/EBITDA | F40: EV/売上高
A41: 株主価値（最小） | B41: =IFERROR(MIN(D31,D32,D33,D34,D35,D37),"") -> -439925.23 | C41: 各手法の最小値
A42: 株主価値（最大） | B42: =IFERROR(MAX(D31,D32,D33,D34,D35,D37),"") -> 10443.88 | C42: 各手法の最大値
A43: 推定評価レンジ | B43: =IFERROR(TEXT(B41,"#,##0")&" 〜 "&TEXT(B42,"#,##0")&" 千円","データ不足") -> -439,925 〜 10,444 千円
A45: 【注記】 ・本算定は帳簿値（修正前）を使用しています。役員報酬の正常化・一時的損益の除外等の調整は「修正後」シートで行ってください。 ・有利子負債は全負債で代替しています。実際は借入金・社債等の有利子負債のみで計算してください。 ・マルチプルはIT業界上場会社の中央値（yfinance参照）を初期値としています。業種・規模に合わせて変更してください。 ・PER法・EV/EBITDA法は赤字の場合参考値となりません。年買法・純資産法を主軸に評価することを推奨します。 ・株主価値 = 事業価値(EV) - 有利子負債。EV = 事業に帰属する価値の総計。

Sheet 企業価値算定（修正後）
A1: 企業価値算定（修正後） ※財務数値を正常化して算定
A2: 単位：千円 黄色セルに調整額を入力してください（プラス＝利益増加・資産増加、マイナス＝利益減少・資産減少）
A3: 【修正項目入力（黄色セルに調整額を入力）】
A4: 修正項目 | B4: 修正内容・理由 | C4: 調整額（千円） | D4: 対象
A5: ①役員報酬の正常化（利益調整） | B5: 現役員報酬 - 同業他社適正水準（例: 過大報酬分を除外し利益を増加） | D5: 経常利益に加算
A6: ②オーナー家族への支払調整（利益） | B6: 過大な家族役員報酬・地代家賃等の正常化 | D6: 経常利益に加算
A7: ③一時的費用の除外（利益） | B7: 再発しない特別費用（訴訟・災害・事業整理等）の除外 | D7: 経常利益に加算
A8: ④一時的収益の除外（利益） | B8: 再発しない特別収益（資産売却・補助金等）の除外 | D8: 経常利益に減算
A9: ⑤役員退職慰労引当等（利益） | B9: 過去分の引当超過や未引当調整 | D9: 経常利益に加減算
A10: ⑥その他利益調整 | B10: 上記以外の利益正常化調整 | D10: 経常利益に加算
A11: ⑦非事業用資産の除外（純資産） | B11: 役員個人的保険・遊休資産・投資有価証券等 | D11: 純資産から除外（減算）
A12: ⑧含み損益の反映（純資産） | B12: 不動産・有価証券の時価と簿価の差額 | D12: 純資産に加算
A13: ⑨簿外負債の考慮（純資産） | B13: 未払退職金・リース・保証債務等の簿外負債 | D13: 純資産から控除（減算）
A14: ⑩その他純資産調整 | B14: 上記以外の純資産正常化調整 | D14: 純資産に加算
A16: 【修正後財務数値（自動計算）】
A17: 修正前 経常利益 | C17: =IFERROR('企業価値算定（修正前）'!B7,0) -> -32413
A18: 利益調整額合計（①〜⑥） | C18: =IFERROR(C5,0)+IFERROR(C6,0)+IFERROR(C7,0)+IFERROR(C8,0)+IFERROR(C9,0)+IFERROR(C10,0) -> 0
A19: 修正後 経常利益 | C19: =C17+C18 -> -32413
A20: 修正前 純資産（簿価） | C20: =IFERROR('企業価値算定（修正前）'!B10,0) -> -24847
A21: 純資産調整額合計（⑦〜⑩） | C21: =IFERROR(C11,0)+IFERROR(C12,0)+IFERROR(C13,0)+IFERROR(C14,0) -> 0
A22: 修正後 純資産 | C22: =C20+C21 -> -24847
A23: 修正後 EBITDA | C23: =C19+IFERROR('企業価値算定（修正前）'!B9,0) -> -28614
A24: 有利子負債合計 | C24: =IFERROR('企業価値算定（修正前）'!B17,0) -> 56339
A26: 【修正後 各評価手法による企業価値算定（千円）】
A27: 評価手法 | B27: 算出根拠 | C27: 事業価値(EV) | D27: 株主価値(EQ) | E27: 修正前比較
A28: ①年倍法（保守的・2年） | C28: =IFERROR(C22+C19*IFERROR('企業価値算定（修正前）'!B22,0),"") -> -89673 | D28: =IFERROR(C28-C24,"") -> -146012 | E28: =IFERROR(D28-'企業価値算定（修正前）'!D31,"") -> 0 | F28: 修正純資産 + 修正経常利益×2年
A29: ②年倍法（楽観的・4年） | C29: =IFERROR(C22+C19*IFERROR('企業価値算定（修正前）'!B23,0),"") -> -154499 | D29: =IFERROR(C29-C24,"") -> -210838 | E29: =IFERROR(D29-'企業価値算定（修正前）'!D32,"") -> 0 | F29: 修正純資産 + 修正経常利益×4年
A30: ③EV/EBITDA法 | C30: =IFERROR(C23*IFERROR('企業価値算定（修正前）'!B24,0),"") -> -348232.38 | D30: =IFERROR(C30-C24,"") -> -404571.38 | E30: =IFERROR(D30-'企業価値算定（修正前）'!D33,"") -> 35353.85 | F30: 修正EBITDA × 倍率
A31: ④EV/売上高法 | C31: =IFERROR('企業価値算定（修正前）'!B4*IFERROR('企業価値算定（修正前）'!B25,0),"") -> 66782.88 | D31: =IFERROR(C31-C24,"") -> 10443.88 | E31: =IFERROR(D31-'企業価値算定（修正前）'!D34,"") -> 0 | F31: 売上高 × 倍率（売上は修正不要）
A32: ⑤PBR法（株主価値ベース） | C32: =IFERROR(D32+C24,"") -> -14971.89 | D32: =IFERROR(C22*IFERROR('企業価値算定（修正前）'!B26,0),"") -> -71310.89 | E32: =IFERROR(D32-'企業価値算定（修正前）'!D35,"") -> 0 | F32: 修正純資産 × PBR
A33: ⑦純資産法（修正後） | C33: =IFERROR(C22+C24,"") -> 31492 | D33: =IFERROR(C22,"") -> -24847 | E33: =IFERROR(D33-'企業価値算定（修正前）'!D37,"") -> 0 | F33: 修正純資産
A35: 【修正後 評価レンジまとめ（株主価値ベース、千円）】
A36: 指標 | B36: 修正後（千円） | C36: 修正前（千円） | D36: 差異（千円）
A37: 株主価値（最小） | B37: =IFERROR(MIN(D28,D29,D30,D31,D32,D33),"") -> -404571.38 | C37: =IFERROR(MIN('企業価値算定（修正前）'!D31,'企業価値算定（修正前）'!D32,'企業価値算定（修正前）'!D33,'企業価値算定（修正前）'!D34,'企業価値算定（修正前）'!D35,'企業価値算定（修正前）'!D37),"") -> -439925.23 | D37: =IFERROR(B37-C37,"") -> 35353.85 | E37: 各手法の最小値
A38: 株主価値（最大） | B38: =IFERROR(MAX(D28,D29,D30,D31,D32,D33),"") -> 10443.88 | C38: =IFERROR(MAX('企業価値算定（修正前）'!D31,'企業価値算定（修正前）'!D32,'企業価値算定（修正前）'!D33,'企業価値算定（修正前）'!D34,'企業価値算定（修正前）'!D35,'企業価値算定（修正前）'!D37),"") -> 10443.88 | D38: =IFERROR(B38-C38,"") -> 0 | E38: 各手法の最大値
A39: 推定評価レンジ（修正後） | B39: =IFERROR(TEXT(B37,"#,##0")&" 〜 "&TEXT(B38,"#,##0")&" 千円","データ不足") -> -404,571 〜 10,444 千円
A41: 【修正項目の考え方】 ①役員報酬の正常化: 現役員報酬が同業他社水準より過大な場合、差額分を利益に戻す（利益=増加→プラス入力） ②家族への過大支払: オーナー家族への過大な役員報酬・地代家賃等を正常化（プラス入力で利益増加） ③④一時的損益: 事業承継後に繰り返さない収益・費用を除外（費用除外→プラス、収益除外→マイナス） ⑦非事業用資産: 事業に不要な資産（役員保険積立金等）を除外（マイナス入力で純資産減少） ⑧含み損益: 不動産や有価証券の時価と簿価の差（含み益→プラス、含み損→マイナス） ⑨簿外負債: 未払退職金・保証債務等（マイナス入力で純資産減少）

Sheet 業界データ
A1: 業種 | B1: 売上総利益率 | C1: 営業利益率 | D1: 経常利益率 | E1: 純利益率 | F1: 自己資本比率 | G1: 流動比率 | H1: 固定比率 | I1: 人件費率 | J1: ROA | K1: ROE | L1: EV/EBITDA | M1: EV/売上高 | N1: PBR | O1: PER
A2: IT・情報通信 | B2: 0.65 | C2: 0.08 | D2: 0.09 | E2: 0.06 | F2: 0.45 | G2: 1.6 | H2: 0.4 | I2: 0.45 | J2: 0.06 | K2: 0.12 | L2: 12 | M2: 2.5 | N2: 2.87 | O2: 23.42
A3: サービス業 | B3: 0.6 | C3: 0.05 | D3: 0.06 | E3: 0.04 | F3: 0.35 | G3: 1.4 | H3: 0.6 | I3: 0.4 | J3: 0.04 | K3: 0.1 | L3: 8 | M3: 1.5 | N3: 1.5 | O3: 15
A4: 製造業 | B4: 0.25 | C4: 0.03 | D4: 0.04 | E4: 0.02 | F4: 0.4 | G4: 1.3 | H4: 0.9 | I4: 0.18 | J4: 0.03 | K4: 0.07 | L4: 7 | M4: 0.8 | N4: 1.2 | O4: 12
A5: 卸売業 | B5: 0.2 | C5: 0.02 | D5: 0.03 | E5: 0.02 | F5: 0.35 | G5: 1.2 | H5: 0.6 | I5: 0.1 | J5: 0.02 | K5: 0.06 | L5: 6 | M5: 0.3 | N5: 1 | O5: 10
A6: 小売業 | B6: 0.3 | C6: 0.02 | D6: 0.03 | E6: 0.02 | F6: 0.3 | G6: 1.1 | H6: 0.8 | I6: 0.15 | J6: 0.02 | K6: 0.07 | L6: 6 | M6: 0.5 | N6: 1.1 | O6: 12
A7: 建設業 | B7: 0.22 | C7: 0.03 | D7: 0.04 | E7: 0.02 | F7: 0.38 | G7: 1.3 | H7: 0.6 | I7: 0.2 | J7: 0.03 | K7: 0.08 | L7: 5 | M7: 0.4 | N7: 1 | O7: 10
A8: 飲食業 | B8: 0.65 | C8: 0.03 | D8: 0.04 | E8: 0.02 | F8: 0.15 | G8: 0.8 | H8: 1.2 | I8: 0.35 | J8: 0.02 | K8: 0.1 | L8: 5 | M8: 0.6 | N8: 1.5 | O8: 15
A9: 不動産業 | B9: 0.55 | C9: 0.15 | D9: 0.16 | E9: 0.1 | F9: 0.4 | G9: 1.2 | H9: 1.5 | I9: 0.1 | J9: 0.05 | K9: 0.12 | L9: 10 | M9: 2 | N9: 1.8 | O9: 18
